"System.AggregateException: One or more errors occurred. (Se ha encontrado un error ORA-12571 de Oracle)\r\n ---> Oracle.ManagedDataAccess.Client.OracleException (0x80004005): Se ha encontrado un error ORA-12571 de Oracle\r\n ---> OracleInternal.Network.NetworkException (0x80004005): Se ha encontrado un error ORA-12571 de Oracle\r\n ---> System.Net.Sockets.SocketException (10054): Se ha forzado la interrupción de una conexión existente por el host remoto.\r\n   at OracleInternal.Network.TcpTransportAdapter.Send(OraBuf OB)\r\n   at OracleInternal.Network.TcpTransportAdapter.Send(OraBuf OB)\r\n   at OracleInternal.Network.WriterStream.Write(OraBuf OB)\r\n   at OracleInternal.TTC.OraBufWriter.FlushData()\r\n   at OracleInternal.TTC.OraBufReader.GetDataFromNetwork()\r\n   at OracleInternal.TTC.OraBufReader.Read(Boolean bIgnoreData)\r\n   at OracleInternal.TTC.TTCSimpleOperations.ReadResponse()\r\n   at Oracle.ManagedDataAccess.Client.OracleException.HandleError(OracleTraceLevel level, OracleTraceTag tag, OracleTraceClassName className, OracleTraceFuncName funcName, Exception ex, OracleLogicalTransaction oracleLogicalTransaction)\r\n   at OracleInternal.TTC.TTCSimpleOperations.ReadResponse()\r\n   at OracleInternal.ServiceObjects.OracleTransactionImpl.Rollback(OracleConnection connection, OracleLogicalTransaction& oracleLogicalTransaction)\r\n   at Oracle.ManagedDataAccess.Client.OracleTransaction.Rollback()\r\n   at Loyal.API.Providers.Auditoria.AuditoriaProvider.SaveFormulario(ProyectoDTO proyecto) in C:\\Users\\HP\\Documents\\AIR-E\\Loyal\\Loyal.API\\Providers\\Auditoria\\AuditoriaProvider.cs:line 562\r\n   --- End of inner exception stack trace ---\r\n   at System.Threading.Tasks.Task`1.GetResultCore(Boolean waitCompletionNotification)\r\n   at System.Threading.Tasks.Task`1.get_Result()\r\n   at Loyal.API.Controllers.AuditoriaController.SaveFormulario(ProyectoDTO proyecto) in C:\\Users\\HP\\Documents\\AIR-E\\Loyal\\Loyal.API\\Controllers\\AuditoriaController.cs:line 153"